##异常框架解析

![](https://img-blog.csdn.net/20180322111107162)

 
#Throwable

	Throwable是 Java 语言中所有错误或异常的超类。
	
	Throwable包含两个子类: Error 和 Exception。它们通常用于指示发生了异常情况。
	
	Throwable包含了其线程创建时线程执行堆栈的快照，它提供了printStackTrace()等接口用于获取堆栈跟踪数据等信息。




#Exception
 
　　Exception及其子类是 Throwable 的一种形式，它指出了合理的应用程序想要捕获的条件。

# RuntimeException 
 
　　RuntimeException是那些可能在 Java 虚拟机正常运行期间抛出的异常的超类。

　　编译器不会检查RuntimeException异常。例如，除数为零时，抛出ArithmeticException异常。RuntimeException是ArithmeticException的超类。当代码发生除数为零的情况时，倘若既"没有通过throws声明抛出ArithmeticException异常"，也"没有通过try...catch...处理该异常"，也能通过编译。这就是我们所说的"编译器不会检查RuntimeException异常"！

　　如果代码会产生RuntimeException异常，则需要通过修改代码进行避免。例如，若会发生除数为零的情况，则需要通过代码避免该情况的发生！
#Error
　　和Exception一样，Error也是Throwable的子类。它用于指示合理的应用程序不应该试图捕获的严重问题，大多数这样的错误都是异常条件。

　　和RuntimeException一样，编译器也不会检查Error。

##


 Java将可抛出(Throwable)的结构分为三种类型：
	被检查的异常(Checked Exception)，运行时异常(RuntimeException)和错误(Error)。


#1.运行时异常

定义: RuntimeException及其子类都被称为运行时异常。

特点: Java编译器不会检查它。也就是说，当程序中可能出现这类异常时，倘若既"没有通过throws声明抛出它"，也"没有用try-catch语句捕获它"，还是会编译通过。例如，除数为零时产生的ArithmeticException异常，数组越界时产生的IndexOutOfBoundsException异常，fail-fail机制产生的ConcurrentModificationException异常等，都属于运行时异常。

虽然Java编译器不会检查运行时异常，但是我们也可以通过throws进行声明抛出，也可以通过try-catch对它进行捕获处理。
如果产生运行时异常，则需要通过修改代码来进行避免。例如，若会发生除数为零的情况，则需要通过代码避免该情况的发生！

#被检查的异常
定义: Exception类本身，以及Exception的子类中除了"运行时异常"之外的其它子类都属于被检查异常。

特点: Java编译器会检查它。此类异常，要么通过throws进行声明抛出，要么通过try-catch进行捕获处理，否则不能通过编译。例如，CloneNotSupportedException就属于被检查异常。当通过clone()接口去克隆一个对象，而该对象对应的类没有实现Cloneable接口，就会抛出CloneNotSupportedException异常。

被检查异常通常都是可以恢复的。

#错误

定义: Error类及其子类。

特点: 和运行时异常一样，编译器也不会对错误进行检查。

　　当资源不足、约束失败、或是其它程序无法继续运行的条件发生时，就产生错误。程序本身无法修复这些错误的。例如，VirtualMachineError就属于错误。

　　按照Java惯例，我们是不应该是实现任何新的Error子类的！



##常见问题
#1.try catch finally 里都有return的 执行顺序

	package com.mk.coffee.test.jdk.resource;
	
	/**
	* @Auther: makui
	* @Date: 2018/12/17
	* @Description: Throwable 所有的Error和Exception的父类
	* 通过此案例 try里面抛异常 虽然里面有return 但是不执行，初始化赋值c=3，然后catch捕获异常 c=0,最终走到finally里面，
	* c=2,虽然try,catch,finally里面都有return，但是finally必须执行，以finally为准。
	*/
	public class Throwable_Exception {
	
	public static int test(int i,int k){
	    int c = 3;
	    try{
	        c = i/k; //java.lang.ArithmeticException: / by zero
	        return 1;
	    }catch (ArithmeticException e){
	       c= 0;
	       return c;
	    }finally {
	        c=  2;
	        return c;
	    }
	}
	public static void main(String[] args) throws Exception {
	    int c = test(1,0);
	    System.out.println(c);
	}
	}

#结论：
1、不管有没有出现异常，finally块中代码都会执行；

2、当try和catch中有return时，finally仍然会执行；

3、finally是在return后面的表达式运算后执行的（此时并没有返回运算后的值，而是先把要返回的值保存起来，不管finally中的代码怎么样，返回的值都不会改变，任然是之前保存的值），所以函数返回值是在finally执行前确定的；

4、finally中最好不要包含return，否则程序会提前退出，返回值不是try或catch中保存的返回值。

举例：

情况1：try{} catch(){}finally{} return;

     显然程序按顺序执行。

情况2:try{ return; }catch(){} finally{} return;
	
	 程序执行try块中return之前（包括return语句中的表达式运算）代码；
	 再执行finally块，最后执行try中return;
	 finally块之后的语句return，因为程序在try中已经return所以不再执行。

情况3:try{ } catch(){return;} finally{} return;

	 程序先执行try，如果遇到异常执行catch块，
	 有异常：则执行catch中return之前（包括return语句中的表达式运算）代码，再执行finally语句中全部代码，
	 最后执行catch块中return. finally之后也就是4处的代码不再执行。
	 无异常：执行完try再finally再return.

情况4:try{ return; }catch(){} finally{return;}

      程序执行try块中return之前（包括return语句中的表达式运算）代码；
      再执行finally块，因为finally块中有return所以提前退出。

情况5:try{} catch(){return;}finally{return;}

          程序执行catch块中return之前（包括return语句中的表达式运算）代码；
          再执行finally块，因为finally块中有return所以提前退出。
情况6:try{ return;}catch(){return;} finally{return;}

          程序执行try块中return之前（包括return语句中的表达式运算）代码；
          有异常：执行catch块中return之前（包括return语句中的表达式运算）代码；
                       则再执行finally块，因为finally块中有return所以提前退出。
          无异常：则再执行finally块，因为finally块中有return所以提前退出。

最终结论：

	任何执行try 或者catch中的return语句之前，都会先执行finally语句，如果finally存在的话。
	如果finally中有return语句，那么程序就return了，所以finally中的return是一定会被return的，
	编译器把finally中的return实现为一个warning。

 